Workbook

Sheet Cover
A2: Financial Statement Analysis
A3: HCL Technologies Ltd. vs Wipro Ltd.
B5: Team Members: | C5: K P Manoj (2025MB26539)
C6: T Venkata Suresh (2025MB26590)
C7: Japleen Kaur Khorana (2025MB26602)
C8: Varsha PS (2025MB26503)
C9: Prashanth G (2025MB26598)
B10: Course: | C10: Financial Management & Accounting
B11: Programme: | C11: MBA in AI for Business
B12: Institution: | C12: BITS Pilani (WILP)
B13: Semester: | C13: 1 - Batch Jan 2026
B14: Period of Analysis: | C14: FY2021 to FY2025
B15: Data Source: | C15: Moneycontrol (Consolidated Statements)

Sheet HCL_Data
A1: HCL Technologies - Consolidated Financial Data (Rs Cr)
A3: BALANCE SHEET
A4: Particulars | B4: FY2025 | C4: FY2024 | D4: FY2023 | E4: FY2022 | F4: FY2021
A5: EQUITIES AND LIABILITIES
A6: SHAREHOLDER'S FUNDS
A7: Equity Share Capital | B7: 543 | C7: 543 | D7: 543 | E7: 543 | F7: 543
A8: Total Share Capital | B8: 543 | C8: 543 | D8: 543 | E8: 543 | F8: 543
A9: Reserves and Surplus | B9: 69112 | C9: 67720 | D9: 64862 | E9: 61371 | F9: 59370
A10: Total Reserves and Surplus | B10: 69112 | C10: 67720 | D10: 64862 | E10: 61371 | F10: 59370
A11: Total Shareholders Funds | B11: 69655 | C11: 68263 | D11: 65405 | E11: 61914 | F11: 59913
A12: Minority Interest | B12: 18 | C12: 8 | D12: -7 | E12: 92 | F12: 169
A13: NON-CURRENT LIABILITIES
A14: Long Term Borrowings | B14: 70 | C14: 2223 | D14: 2111 | E14: 3923 | F14: 3828
A15: Deferred Tax Liabilities [Net] | B15: 1615 | C15: 771 | D15: 161 | E15: 112 | F15: 147
A16: Other Long Term Liabilities | B16: 4227 | C16: 4174 | D16: 2995 | E16: 2802 | F16: 3421
A17: Long Term Provisions | B17: 1920 | C17: 1612 | D17: 1315 | E17: 1415 | F17: 1333
A18: Total Non-Current Liabilities | B18: 7832 | C18: 8780 | D18: 6582 | E18: 8252 | F18: 8729
A19: CURRENT LIABILITIES
A20: Short Term Borrowings | B20: 2221 | C20: 104 | D20: 140 | E20: 62 | F20: 0
A21: Trade Payables | B21: 13234 | C21: 5853 | D21: 6428 | E21: 6278 | F21: 1726 | G21: 1166
A22: Other Current Liabilities | B22: 11097 | C22: 15432 | D22: 13743 | E22: 11480 | F22: 14694
A23: Short Term Provisions | B23: 1487 | C23: 1337 | D23: 1120 | E23: 955 | F23: 963
A24: Total Current Liabilities | B24: 28039 | C24: 22726 | D24: 21431 | E24: 18775 | F24: 17383
A25: Total Capital And Liabilities | B25: 105544 | C25: 99777 | D25: 93411 | E25: 89033 | F25: 86194
A26: ASSETS
A27: NON-CURRENT ASSETS
A28: Tangible Assets | B28: 7517 | C28: 7801 | D28: 7708 | E28: 7917 | F28: 8052
A29: Intangible Assets | B29: 6899 | C29: 7130 | D29: 8344 | E29: 9743 | F29: 11901
A30: Capital Work-In-Progress | B30: 59 | C30: 108 | D30: 40 | E30: 129 | F30: 312
A31: Fixed Assets | B31: 14475 | C31: 15039 | D31: 16092 | E31: 17789 | F31: 20265
A32: Non-Current Investments | B32: 91 | C32: 94 | D32: 110 | E32: 112 | F32: 89
A33: Deferred Tax Assets [Net] | B33: 1064 | C33: 1031 | D33: 1252 | E33: 1176 | F33: 1181
A34: Long Term Loans And Advances | B34: 586 | C34: 286 | D34: 0 | E34: 200 | F34: 0
A35: Other Non-Current Assets | B35: 5463 | C35: 3864 | D35: 3813 | E35: 4298 | F35: 4416
A36: Total Non-Current Assets | B36: 43435 | C36: 40446 | D36: 39834 | E36: 40992 | F36: 43143
A37: CURRENT ASSETS
A38: Current Investments | B38: 7473 | C38: 7043 | D38: 5385 | E38: 6239 | F38: 6773
A39: Inventories | B39: 133 | C39: 185 | D39: 228 | E39: 161 | F39: 94 | G39: 91
A40: Trade Receivables | B40: 25842 | C40: 25521 | D40: 25506 | E40: 20671 | F40: 13663 | G40: 14131
A41: Cash And Cash Equivalents | B41: 21289 | C41: 20150 | D41: 14724 | E41: 12636 | F41: 8888
...

Sheet Wipro_Data
A1: Wipro Ltd. - Consolidated Financial Data (Rs Cr)
A3: BALANCE SHEET
A4: Particulars | B4: FY2025 | C4: FY2024 | D4: FY2023 | E4: FY2022 | F4: FY2021
A5: EQUITIES AND LIABILITIES
A6: SHAREHOLDER'S FUNDS
A7: Equity Share Capital | B7: 2094.4 | C7: 1045 | D7: 1097.6 | E7: 1096.4 | F7: 1095.8
A8: Total Share Capital | B8: 2094.4 | C8: 1045 | D8: 1097.6 | E8: 1096.4 | F8: 1095.8
A9: Reserves and Surplus | B9: 80269.7 | C9: 73488 | D9: 76570.3 | E9: 64306.6 | F9: 53805.2
A10: Total Reserves and Surplus | B10: 80269.7 | C10: 73488 | D10: 76570.3 | E10: 64306.6 | F10: 53805.2
A11: Total Shareholders Funds | B11: 82364.1 | C11: 74533 | D11: 77667.9 | E11: 65403 | F11: 54901
A12: Minority Interest | B12: 213.8 | C12: 134 | D12: 58.9 | E12: 51.5 | F12: 149.8
A13: NON-CURRENT LIABILITIES
A14: Long Term Borrowings | B14: 6395.4 | C14: 6230 | D14: 6127.2 | E14: 5646.3 | F14: 745.8
A15: Deferred Tax Liabilities [Net] | B15: 1644.3 | C15: 1746.7 | D15: 1515.3 | E15: 1214.1 | F15: 460.6
A16: Other Long Term Liabilities | B16: 8476.7 | C16: 6479.2 | D16: 4694.4 | E16: 4085.5 | F16: 3165.3
A17: Long Term Provisions | B17: 465.6 | C17: 421.9 | D17: 294.7 | E17: 272.1 | F17: 305.7
A18: Total Non-Current Liabilities | B18: 16982 | C18: 14877.8 | D18: 12631.6 | E18: 11218 | F18: 4677.4
A19: CURRENT LIABILITIES
A20: Short Term Borrowings | B20: 9786.3 | C20: 7916.6 | D20: 8882.1 | E20: 9523.3 | F20: 6036.3
A21: Trade Payables | B21: 5866.7 | C21: 5765.5 | D21: 5972.3 | E21: 6252.2 | F21: 5417.4 | G21: 5840
A22: Other Current Liabilities | B22: 11208.5 | C22: 9760.9 | D22: 10077.5 | E22: 13249.3 | F22: 10002.5
A23: Short Term Provisions | B23: 1763.8 | C23: 1802.8 | D23: 1843.4 | E23: 1808.1 | F23: 1547.8
A24: Total Current Liabilities | B24: 28625.3 | C24: 25245.8 | D24: 26775.3 | E24: 30832.9 | F24: 23004
A25: Total Capital And Liabilities | B25: 128185.2 | C25: 114790.6 | D25: 117133.7 | E25: 107505.4 | F25: 82732.2
A26: ASSETS
A27: NON-CURRENT ASSETS
A28: Tangible Assets | B28: 10407.1 | C28: 9208.3 | D28: 10103.8 | E28: 9348 | F28: 8217.1
A29: Intangible Assets | B29: 2745 | C29: 3274.8 | D29: 4304.5 | E29: 4355.5 | F29: 1308.5
A30: Capital Work-In-Progress | B30: 196.4 | C30: 723.4 | D30: 617.1 | E30: 1601.5 | F30: 1853.2
A31: Fixed Assets | B31: 13348.5 | C31: 13206.5 | D31: 15025.4 | E31: 15305 | F31: 11378.8
A32: Non-Current Investments | B32: 2778.5 | C32: 2267.3 | D32: 2150 | E32: 1988.3 | F32: 1204
A33: Deferred Tax Assets [Net] | B33: 256.1 | C33: 181.7 | D33: 210 | E33: 229.8 | F33: 166.4
A34: Long Term Loans And Advances | B34: 0 | C34: 0 | D34: 0 | E34: 0 | F34: 0
A35: Other Non-Current Assets | B35: 1990 | C35: 2924 | D35: 3290.2 | E35: 3621 | F35: 4149.7
A36: Total Non-Current Assets | B36: 50407.7 | C36: 49724.4 | D36: 51024.1 | E36: 45430.2 | F36: 30413.6
A37: CURRENT ASSETS
A38: Current Investments | B38: 41147.4 | C38: 31117.1 | D38: 30923.2 | E38: 24165.5 | F38: 17570.7
A39: Inventories | B39: 69.4 | C39: 90.7 | D39: 118.8 | E39: 133.4 | F39: 106.4 | G39: 186.5
A40: Trade Receivables | B40: 11774.5 | C40: 17382.2 | D40: 18686.5 | E40: 11521.9 | F40: 9429.8 | G40: 10447.4
A41: Cash And Cash Equivalents | B41: 12197.4 | C41: 9695.3 | D41: 9188 | E41: 10383.6 | F41: 16979.3
...

Sheet Ratios
A1: Financial Ratios - HCL Technologies vs Wipro (FY2021-FY2025)
B3: HCL Technologies | H3: Wipro
A4: Ratio | B4: HCL FY2025 | C4: HCL FY2024 | D4: HCL FY2023 | E4: HCL FY2022 | F4: HCL FY2021 | H4: Wipro FY2025 | I4: Wipro FY2024 | J4: Wipro FY2023 | K4: Wipro FY2022 | L4: Wipro FY2021
A5: LIQUIDITY RATIOS
A6: Current Ratio | B6: =HCL_Data!B44/HCL_Data!B24 | C6: =HCL_Data!C44/HCL_Data!C24 | D6: =HCL_Data!D44/HCL_Data!D24 | E6: =HCL_Data!E44/HCL_Data!E24 | F6: =HCL_Data!F44/HCL_Data!F24 | H6: =Wipro_Data!B44/Wipro_Data!B24 | I6: =Wipro_Data!C44/Wipro_Data!C24 | J6: =Wipro_Data!D44/Wipro_Data!D24 | K6: =Wipro_Data!E44/Wipro_Data!E24 | L6: =Wipro_Data!F44/Wipro_Data!F24
A7: Quick Ratio | B7: =(HCL_Data!B44-HCL_Data!B39)/HCL_Data!B24 | C7: =(HCL_Data!C44-HCL_Data!C39)/HCL_Data!C24 | D7: =(HCL_Data!D44-HCL_Data!D39)/HCL_Data!D24 | E7: =(HCL_Data!E44-HCL_Data!E39)/HCL_Data!E24 | F7: =(HCL_Data!F44-HCL_Data!F39)/HCL_Data!F24 | H7: =(Wipro_Data!B44-Wipro_Data!B39)/Wipro_Data!B24 | I7: =(Wipro_Data!C44-Wipro_Data!C39)/Wipro_Data!C24 | J7: =(Wipro_Data!D44-Wipro_Data!D39)/Wipro_Data!D24 | K7: =(Wipro_Data!E44-Wipro_Data!E39)/Wipro_Data!E24 | L7: =(Wipro_Data!F44-Wipro_Data!F39)/Wipro_Data!F24
A8: Absolute Liquid Ratio | B8: =(HCL_Data!B41+HCL_Data!B38)/HCL_Data!B24 | C8: =(HCL_Data!C41+HCL_Data!C38)/HCL_Data!C24 | D8: =(HCL_Data!D41+HCL_Data!D38)/HCL_Data!D24 | E8: =(HCL_Data!E41+HCL_Data!E38)/HCL_Data!E24 | F8: =(HCL_Data!F41+HCL_Data!F38)/HCL_Data!F24 | H8: =(Wipro_Data!B41+Wipro_Data!B38)/Wipro_Data!B24 | I8: =(Wipro_Data!C41+Wipro_Data!C38)/Wipro_Data!C24 | J8: =(Wipro_Data!D41+Wipro_Data!D38)/Wipro_Data!D24 | K8: =(Wipro_Data!E41+Wipro_Data!E38)/Wipro_Data!E24 | L8: =(Wipro_Data!F41+Wipro_Data!F38)/Wipro_Data!F24
A9: PROFITABILITY RATIOS
A10: Gross Profit Ratio (%) | B10: =(HCL_Data!B63-(HCL_Data!B69+HCL_Data!B70+HCL_Data!B71))/HCL_Data!B63*100 | C10: =(HCL_Data!C63-(HCL_Data!C69+HCL_Data!C70+HCL_Data!C71))/HCL_Data!C63*100 | D10: =(HCL_Data!D63-(HCL_Data!D69+HCL_Data!D70+HCL_Data!D71))/HCL_Data!D63*100 | E10: =(HCL_Data!E63-(HCL_Data!E69+HCL_Data!E70+HCL_Data!E71))/HCL_Data!E63*100 | F10: =(HCL_Data!F63-(HCL_Data!F69+HCL_Data!F70+HCL_Data!F71))/HCL_Data!F63*100 | H10: =(Wipro_Data!B63-(Wipro_Data!B69+Wipro_Data!B70+Wipro_Data!B71))/Wipro_Data!B63*100 | I10: =(Wipro_Data!C63-(Wipro_Data!C69+Wipro_Data!C70+Wipro_Data!C71))/Wipro_Data!C63*100 | J10: =(Wipro_Data!D63-(Wipro_Data!D69+Wipro_Data!D70+Wipro_Data!D71))/Wipro_Data!D63*100 | K10: =(Wipro_Data!E63-(Wipro_Data!E69+Wipro_Data!E70+Wipro_Data!E71))/Wipro_Data!E63*100 | L10: =(Wipro_Data!F63-(Wipro_Data!F69+Wipro_Data!F70+Wipro_Data!F71))/Wipro_Data!F63*100
A11: Operating Profit Ratio (%) | B11: =(HCL_Data!B79+HCL_Data!B73)/HCL_Data!B63*100 | C11: =(HCL_Data!C79+HCL_Data!C73)/HCL_Data!C63*100 | D11: =(HCL_Data!D79+HCL_Data!D73)/HCL_Data!D63*100 | E11: =(HCL_Data!E79+HCL_Data!E73)/HCL_Data!E63*100 | F11: =(HCL_Data!F79+HCL_Data!F73)/HCL_Data!F63*100 | H11: =(Wipro_Data!B79+Wipro_Data!B73)/Wipro_Data!B63*100 | I11: =(Wipro_Data!C79+Wipro_Data!C73)/Wipro_Data!C63*100 | J11: =(Wipro_Data!D79+Wipro_Data!D73)/Wipro_Data!D63*100 | K11: =(Wipro_Data!E79+Wipro_Data!E73)/Wipro_Data!E63*100 | L11: =(Wipro_Data!F79+Wipro_Data!F73)/Wipro_Data!F63*100
A12: Net Profit Ratio (%) | B12: =HCL_Data!B88/HCL_Data!B63*100 | C12: =HCL_Data!C88/HCL_Data!C63*100 | D12: =HCL_Data!D88/HCL_Data!D63*100 | E12: =HCL_Data!E88/HCL_Data!E63*100 | F12: =HCL_Data!F88/HCL_Data!F63*100 | H12: =Wipro_Data!B88/Wipro_Data!B63*100 | I12: =Wipro_Data!C88/Wipro_Data!C63*100 | J12: =Wipro_Data!D88/Wipro_Data!D63*100 | K12: =Wipro_Data!E88/Wipro_Data!E63*100 | L12: =Wipro_Data!F88/Wipro_Data!F63*100
A13: Return on Equity (%) | B13: =HCL_Data!B88/((HCL_Data!B11+HCL_Data!C11)/2)*100 | C13: =HCL_Data!C88/((HCL_Data!C11+HCL_Data!D11)/2)*100 | D13: =HCL_Data!D88/((HCL_Data!D11+HCL_Data!E11)/2)*100 | E13: =HCL_Data!E88/((HCL_Data!E11+HCL_Data!F11)/2)*100 | F13: =HCL_Data!F88/((HCL_Data!F11+HCL_Data!F11)/2)*100 | H13: =Wipro_Data!B88/((Wipro_Data!B11+Wipro_Data!C11)/2)*100 | I13: =Wipro_Data!C88/((Wipro_Data!C11+Wipro_Data!D11)/2)*100 | J13: =Wipro_Data!D88/((Wipro_Data!D11+Wipro_Data!E11)/2)*100 | K13: =Wipro_Data!E88/((Wipro_Data!E11+Wipro_Data!F11)/2)*100 | L13: =Wipro_Data!F88/((Wipro_Data!F11+Wipro_Data!F11)/2)*100
A14: Return on Capital Employed (%) | B14: =(HCL_Data!B79+HCL_Data!B73)/(HCL_Data!B45-HCL_Data!B24)*100 | C14: =(HCL_Data!C79+HCL_Data!C73)/(HCL_Data!C45-HCL_Data!C24)*100 | D14: =(HCL_Data!D79+HCL_Data!D73)/(HCL_Data!D45-HCL_Data!D24)*100 | E14: =(HCL_Data!E79+HCL_Data!E73)/(HCL_Data!E45-HCL_Data!E24)*100 | F14: =(HCL_Data!F79+HCL_Data!F73)/(HCL_Data!F45-HCL_Data!F24)*100 | H14: =(Wipro_Data!B79+Wipro_Data!B73)/(Wipro_Data!B45-Wipro_Data!B24)*100 | I14: =(Wipro_Data!C79+Wipro_Data!C73)/(Wipro_Data!C45-Wipro_Data!C24)*100 | J14: =(Wipro_Data!D79+Wipro_Data!D73)/(Wipro_Data!D45-Wipro_Data!D24)*100 | K14: =(Wipro_Data!E79+Wipro_Data!E73)/(Wipro_Data!E45-Wipro_Data!E24)*100 | L14: =(Wipro_Data!F79+Wipro_Data!F73)/(Wipro_Data!F45-Wipro_Data!F24)*100
A15: Earnings per Share (Rs) | B15: =HCL_Data!B90/(HCL_Data!B7/2) | C15: =HCL_Data!C90/(HCL_Data!C7/2) | D15: =HCL_Data!D90/(HCL_Data!D7/2) | E15: =HCL_Data!E90/(HCL_Data!E7/2) | F15: =HCL_Data!F90/(HCL_Data!F7/2) | H15: =Wipro_Data!B90/(Wipro_Data!B7/2) | I15: =Wipro_Data!C90/(Wipro_Data!C7/2) | J15: =Wipro_Data!D90/(Wipro_Data!D7/2) | K15: =Wipro_Data!E90/(Wipro_Data!E7/2) | L15: =Wipro_Data!F90/(Wipro_Data!F7/2)
A16: SOLVENCY RATIOS
A17: Debt-Equity Ratio | B17: =(HCL_Data!B14+HCL_Data!B20)/HCL_Data!B11 | C17: =(HCL_Data!C14+HCL_Data!C20)/HCL_Data!C11 | D17: =(HCL_Data!D14+HCL_Data!D20)/HCL_Data!D11 | E17: =(HCL_Data!E14+HCL_Data!E20)/HCL_Data!E11 | F17: =(HCL_Data!F14+HCL_Data!F20)/HCL_Data!F11 | H17: =(Wipro_Data!B14+Wipro_Data!B20)/Wipro_Data!B11 | I17: =(Wipro_Data!C14+Wipro_Data!C20)/Wipro_Data!C11 | J17: =(Wipro_Data!D14+Wipro_Data!D20)/Wipro_Data!D11 | K17: =(Wipro_Data!E14+Wipro_Data!E20)/Wipro_Data!E11 | L17: =(Wipro_Data!F14+Wipro_Data!F20)/Wipro_Data!F11
A18: Interest Coverage Ratio | B18: =(HCL_Data!B79+HCL_Data!B73)/HCL_Data!B73 | C18: =(HCL_Data!C79+HCL_Data!C73)/HCL_Data!C73 | D18: =(HCL_Data!D79+HCL_Data!D73)/HCL_Data!D73 | E18: =(HCL_Data!E79+HCL_Data!E73)/HCL_Data!E73 | F18: =(HCL_Data!F79+HCL_Data!F73)/HCL_Data!F73 | H18: =(Wipro_Data!B79+Wipro_Data!B73)/Wipro_Data!B73 | I18: =(Wipro_Data!C79+Wipro_Data!C73)/Wipro_Data!C73 | J18: =(Wipro_Data!D79+Wipro_Data!D73)/Wipro_Data!D73 | K18: =(Wipro_Data!E79+Wipro_Data!E73)/Wipro_Data!E73 | L18: =(Wipro_Data!F79+Wipro_Data!F73)/Wipro_Data!F73
A19: TURNOVER RATIOS
A20: Debtors Turnover Ratio | B20: =HCL_Data!B63/((HCL_Data!B40+HCL_Data!C40)/2) | C20: =HCL_Data!C63/((HCL_Data!C40+HCL_Data!D40)/2) | D20: =HCL_Data!D63/((HCL_Data!D40+HCL_Data!E40)/2) | E20: =HCL_Data!E63/((HCL_Data!E40+HCL_Data!F40)/2) | F20: =HCL_Data!F63/((HCL_Data!F40+HCL_Data!F40)/2) | H20: =Wipro_Data!B63/((Wipro_Data!B40+Wipro_Data!C40)/2) | I20: =Wipro_Data!C63/((Wipro_Data!C40+Wipro_Data!D40)/2) | J20: =Wipro_Data!D63/((Wipro_Data!D40+Wipro_Data!E40)/2) | K20: =Wipro_Data!E63/((Wipro_Data!E40+Wipro_Data!F40)/2) | L20: =Wipro_Data!F63/((Wipro_Data!F40+Wipro_Data!F40)/2)
A21: Avg Collection Period (days) | B21: =365/(HCL_Data!B63/((HCL_Data!B40+HCL_Data!C40)/2)) | C21: =365/(HCL_Data!C63/((HCL_Data!C40+HCL_Data!D40)/2)) | D21: =365/(HCL_Data!D63/((HCL_Data!D40+HCL_Data!E40)/2)) | E21: =365/(HCL_Data!E63/((HCL_Data!E40+HCL_Data!F40)/2)) | F21: =365/(HCL_Data!F63/((HCL_Data!F40+HCL_Data!F40)/2)) | H21: =365/(Wipro_Data!B63/((Wipro_Data!B40+Wipro_Data!C40)/2)) | I21: =365/(Wipro_Data!C63/((Wipro_Data!C40+Wipro_Data!D40)/2)) | J21: =365/(Wipro_Data!D63/((Wipro_Data!D40+Wipro_Data!E40)/2)) | K21: =365/(Wipro_Data!E63/((Wipro_Data!E40+Wipro_Data!F40)/2)) | L21: =365/(Wipro_Data!F63/((Wipro_Data!F40+Wipro_Data!F40)/2))
A22: Creditors Turnover Ratio | B22: =(HCL_Data!B69+HCL_Data!B70+HCL_Data!B75)/((HCL_Data!B21+HCL_Data!C21)/2) | C22: =(HCL_Data!C69+HCL_Data!C70+HCL_Data!C75)/((HCL_Data!C21+HCL_Data!D21)/2) | D22: =(HCL_Data!D69+HCL_Data!D70+HCL_Data!D75)/((HCL_Data!D21+HCL_Data!E21)/2) | E22: =(HCL_Data!E69+HCL_Data!E70+HCL_Data!E75)/((HCL_Data!E21+HCL_Data!F21)/2) | F22: =(HCL_Data!F69+HCL_Data!F70+HCL_Data!F75)/((HCL_Data!F21+HCL_Data!F21)/2) | H22: =(Wipro_Data!B69+Wipro_Data!B70+Wipro_Data!B75)/((Wipro_Data!B21+Wipro_Data!C21)/2) | I22: =(Wipro_Data!C69+Wipro_Data!C70+Wipro_Data!C75)/((Wipro_Data!C21+Wipro_Data!D21)/2) | J22: =(Wipro_Data!D69+Wipro_Data!D70+Wipro_Data!D75)/((Wipro_Data!D21+Wipro_Data!E21)/2) | K22: =(Wipro_Data!E69+Wipro_Data!E70+Wipro_Data!E75)/((Wipro_Data!E21+Wipro_Data!F21)/2) | L22: =(Wipro_Data!F69+Wipro_Data!F70+Wipro_Data!F75)/((Wipro_Data!F21+Wipro_Data!F21)/2)
A23: Avg Payment Period (days) | B23: =365/((HCL_Data!B69+HCL_Data!B70+HCL_Data!B75)/((HCL_Data!B21+HCL_Data!C21)/2)) | C23: =365/((HCL_Data!C69+HCL_Data!C70+HCL_Data!C75)/((HCL_Data!C21+HCL_Data!D21)/2)) | D23: =365/((HCL_Data!D69+HCL_Data!D70+HCL_Data!D75)/((HCL_Data!D21+HCL_Data!E21)/2)) | E23: =365/((HCL_Data!E69+HCL_Data!E70+HCL_Data!E75)/((HCL_Data!E21+HCL_Data!F21)/2)) | F23: =365/((HCL_Data!F69+HCL_Data!F70+HCL_Data!F75)/((HCL_Data!F21+HCL_Data!F21)/2)) | H23: =365/((Wipro_Data!B69+Wipro_Data!B70+Wipro_Data!B75)/((Wipro_Data!B21+Wipro_Data!C21)/2)) | I23: =365/((Wipro_Data!C69+Wipro_Data!C70+Wipro_Data!C75)/((Wipro_Data!C21+Wipro_Data!D21)/2)) | J23: =365/((Wipro_Data!D69+Wipro_Data!D70+Wipro_Data!D75)/((Wipro_Data!D21+Wipro_Data!E21)/2)) | K23: =365/((Wipro_Data!E69+Wipro_Data!E70+Wipro_Data!E75)/((Wipro_Data!E21+Wipro_Data!F21)/2)) | L23: =365/((Wipro_Data!F69+Wipro_Data!F70+Wipro_Data!F75)/((Wipro_Data!F21+Wipro_Data!F21)/2))
A24: Inventory Turnover Ratio | B24: =(HCL_Data!B69+HCL_Data!B70+HCL_Data!B71)/((HCL_Data!B39+HCL_Data!C39)/2) | C24: =(HCL_Data!C69+HCL_Data!C70+HCL_Data!C71)/((HCL_Data!C39+HCL_Data!D39)/2) | D24: =(HCL_Data!D69+HCL_Data!D70+HCL_Data!D71)/((HCL_Data!D39+HCL_Data!E39)/2) | E24: =(HCL_Data!E69+HCL_Data!E70+HCL_Data!E71)/((HCL_Data!E39+HCL_Data!F39)/2) | F24: =(HCL_Data!F69+HCL_Data!F70+HCL_Data!F71)/((HCL_Data!F39+HCL_Data!F39)/2) | H24: =(Wipro_Data!B69+Wipro_Data!B70+Wipro_Data!B71)/((Wipro_Data!B39+Wipro_Data!C39)/2) | I24: =(Wipro_Data!C69+Wipro_Data!C70+Wipro_Data!C71)/((Wipro_Data!C39+Wipro_Data!D39)/2) | J24: =(Wipro_Data!D69+Wipro_Data!D70+Wipro_Data!D71)/((Wipro_Data!D39+Wipro_Data!E39)/2) | K24: =(Wipro_Data!E69+Wipro_Data!E70+Wipro_Data!E71)/((Wipro_Data!E39+Wipro_Data!F39)/2) | L24: =(Wipro_Data!F69+Wipro_Data!F70+Wipro_Data!F71)/((Wipro_Data!F39+Wipro_Data!F39)/2)
A25: Inventory Holding Days | B25: =365/((HCL_Data!B69+HCL_Data!B70+HCL_Data!B71)/((HCL_Data!B39+HCL_Data!C39)/2)) | C25: =365/((HCL_Data!C69+HCL_Data!C70+HCL_Data!C71)/((HCL_Data!C39+HCL_Data!D39)/2)) | D25: =365/((HCL_Data!D69+HCL_Data!D70+HCL_Data!D71)/((HCL_Data!D39+HCL_Data!E39)/2)) | E25: =365/((HCL_Data!E69+HCL_Data!E70+HCL_Data!E71)/((HCL_Data!E39+HCL_Data!F39)/2)) | F25: =365/((HCL_Data!F69+HCL_Data!F70+HCL_Data!F71)/((HCL_Data!F39+HCL_Data!F39)/2)) | H25: =365/((Wipro_Data!B69+Wipro_Data!B70+Wipro_Data!B71)/((Wipro_Data!B39+Wipro_Data!C39)/2)) | I25: =365/((Wipro_Data!C69+Wipro_Data!C70+Wipro_Data!C71)/((Wipro_Data!C39+Wipro_Data!D39)/2)) | J25: =365/((Wipro_Data!D69+Wipro_Data!D70+Wipro_Data!D71)/((Wipro_Data!D39+Wipro_Data!E39)/2)) | K25: =365/((Wipro_Data!E69+Wipro_Data!E70+Wipro_Data!E71)/((Wipro_Data!E39+Wipro_Data!F39)/2)) | L25: =365/((Wipro_Data!F69+Wipro_Data!F70+Wipro_Data!F71)/((Wipro_Data!F39+Wipro_Data!F39)/2))
A26: Fixed Asset Turnover | B26: =HCL_Data!B63/((HCL_Data!B31+HCL_Data!C31)/2) | C26: =HCL_Data!C63/((HCL_Data!C31+HCL_Data!D31)/2) | D26: =HCL_Data!D63/((HCL_Data!D31+HCL_Data!E31)/2) | E26: =HCL_Data!E63/((HCL_Data!E31+HCL_Data!F31)/2) | F26: =HCL_Data!F63/((HCL_Data!F31+HCL_Data!F31)/2) | H26: =Wipro_Data!B63/((Wipro_Data!B31+Wipro_Data!C31)/2) | I26: =Wipro_Data!C63/((Wipro_Data!C31+Wipro_Data!D31)/2) | J26: =Wipro_Data!D63/((Wipro_Data!D31+Wipro_Data!E31)/2) | K26: =Wipro_Data!E63/((Wipro_Data!E31+Wipro_Data!F31)/2) | L26: =Wipro_Data!F63/((Wipro_Data!F31+Wipro_Data!F31)/2)
A27: VALUATION RATIOS
A28: Price/BV (X) from Money Control | B28: 6.2 | C28: 6.14 | D28: 4.51 | E28: 5.1 | F28: 4.46 | H28: 3.33 | I28: 3.37 | J28: 2.58 | K28: 4.96 | L28: 4.13
A29: Book Value/Share (Rs.) from Money Control | B29: 256.56 | C29: 251.46 | D29: 240.88 | E29: 228.38 | F29: 221.3 | H29: 78.65 | I29: 142.65 | J29: 141.63 | K29: 119.4 | L29: 100.48
A30: P/E Ratio | B30: =(B28*B29)/B15 | C30: =(C28*C29)/C15 | D30: =(D28*D29)/D15 | E30: =(E28*E29)/E15 | F30: =(F28*F29)/F15 | H30: =(H28*H29)/H15 | I30: =(I28*I29)/I15 | J30: =(J28*J29)/J15 | K30: =(K28*K29)/K15 | L30: =(L28*L29)/L15

Sheet DuPont
A1: DuPont Analysis - HCL Technologies vs Wipro
B3: HCL Technologies | H3: Wipro
A4: Component | B4: FY2025 | C4: FY2024 | D4: FY2023 | E4: FY2022 | F4: FY2021 | H4: FY2025 | I4: FY2024 | J4: FY2023 | K4: FY2022 | L4: FY2021
A5: Net Profit Margin | B5: =HCL_Data!B86/HCL_Data!B63 | C5: =HCL_Data!C86/HCL_Data!C63 | D5: =HCL_Data!D86/HCL_Data!D63 | E5: =HCL_Data!E86/HCL_Data!E63 | F5: =HCL_Data!F86/HCL_Data!F63 | H5: =Wipro_Data!B86/Wipro_Data!B63 | I5: =Wipro_Data!C86/Wipro_Data!C63 | J5: =Wipro_Data!D86/Wipro_Data!D63 | K5: =Wipro_Data!E86/Wipro_Data!E63 | L5: =Wipro_Data!F86/Wipro_Data!F63
A6: Asset Turnover | B6: =HCL_Data!B63/HCL_Data!B45 | C6: =HCL_Data!C63/HCL_Data!C45 | D6: =HCL_Data!D63/HCL_Data!D45 | E6: =HCL_Data!E63/HCL_Data!E45 | F6: =HCL_Data!F63/HCL_Data!F45 | H6: =Wipro_Data!B63/Wipro_Data!B45 | I6: =Wipro_Data!C63/Wipro_Data!C45 | J6: =Wipro_Data!D63/Wipro_Data!D45 | K6: =Wipro_Data!E63/Wipro_Data!E45 | L6: =Wipro_Data!F63/Wipro_Data!F45
A7: Equity Multiplier | B7: =HCL_Data!B45/HCL_Data!B11 | C7: =HCL_Data!C45/HCL_Data!C11 | D7: =HCL_Data!D45/HCL_Data!D11 | E7: =HCL_Data!E45/HCL_Data!E11 | F7: =HCL_Data!F45/HCL_Data!F11 | H7: =Wipro_Data!B45/Wipro_Data!B11 | I7: =Wipro_Data!C45/Wipro_Data!C11 | J7: =Wipro_Data!D45/Wipro_Data!D11 | K7: =Wipro_Data!E45/Wipro_Data!E11 | L7: =Wipro_Data!F45/Wipro_Data!F11
A9: ROE via DuPont (%) | B9: =B5*B6*B7*100 | C9: =C5*C6*C7*100 | D9: =D5*D6*D7*100 | E9: =E5*E6*E7*100 | F9: =F5*F6*F7*100 | H9: =H5*H6*H7*100 | I9: =I5*I6*I7*100 | J9: =J5*J6*J7*100 | K9: =K5*K6*K7*100 | L9: =L5*L6*L7*100

Sheet CCC
A1: Cash Conversion Cycle - HCL Technologies vs Wipro
B3: HCL Technologies | H3: Wipro
A4: Component (days) | B4: FY2025 | C4: FY2024 | D4: FY2023 | E4: FY2022 | F4: FY2021 | H4: FY2025 | I4: FY2024 | J4: FY2023 | K4: FY2022 | L4: FY2021
A5: Days Inventory Outstanding (DIO) | B5: =(365*(HCL_Data!B39+HCL_Data!C39)/2)/(HCL_Data!B69+HCL_Data!B70+HCL_Data!B71) | C5: =(365*(HCL_Data!C39+HCL_Data!D39)/2)/(HCL_Data!C69+HCL_Data!C70+HCL_Data!C71) | D5: =(365*(HCL_Data!D39+HCL_Data!E39)/2)/(HCL_Data!D69+HCL_Data!D70+HCL_Data!D71) | E5: =(365*(HCL_Data!E39+HCL_Data!F39)/2)/(HCL_Data!E69+HCL_Data!E70+HCL_Data!E71) | F5: =(365*(HCL_Data!F39+91)/2)/(HCL_Data!F69+HCL_Data!F70+HCL_Data!F71) | H5: =(365*(Wipro_Data!B39+Wipro_Data!C39)/2)/(Wipro_Data!B69+Wipro_Data!B70+Wipro_Data!B71) | I5: =(365*(Wipro_Data!C39+Wipro_Data!D39)/2)/(Wipro_Data!C69+Wipro_Data!C70+Wipro_Data!C71) | J5: =(365*(Wipro_Data!D39+Wipro_Data!E39)/2)/(Wipro_Data!D69+Wipro_Data!D70+Wipro_Data!D71) | K5: =(365*(Wipro_Data!E39+Wipro_Data!F39)/2)/(Wipro_Data!E69+Wipro_Data!E70+Wipro_Data!E71) | L5: =(365*(Wipro_Data!F39+Wipro_Data!G39)/2)/(Wipro_Data!F69+Wipro_Data!F70+Wipro_Data!F71)
A6: Days Sales Outstanding (DSO) | B6: =(365*((HCL_Data!B40+HCL_Data!C40)/2))/HCL_Data!B63 | C6: =(365*((HCL_Data!C40+HCL_Data!D40)/2))/HCL_Data!C63 | D6: =(365*((HCL_Data!D40+HCL_Data!E40)/2))/HCL_Data!D63 | E6: =(365*((HCL_Data!E40+HCL_Data!F40)/2))/HCL_Data!E63 | F6: =(365*((HCL_Data!F40+HCL_Data!G40)/2))/HCL_Data!F63 | H6: =(365*((Wipro_Data!B40+Wipro_Data!C40)/2))/Wipro_Data!B63 | I6: =(365*((Wipro_Data!C40+Wipro_Data!D40)/2))/Wipro_Data!C63 | J6: =(365*((Wipro_Data!D40+Wipro_Data!E40)/2))/Wipro_Data!D63 | K6: =(365*((Wipro_Data!E40+Wipro_Data!F40)/2))/Wipro_Data!E63 | L6: =(365*((Wipro_Data!F40+Wipro_Data!G40)/2))/Wipro_Data!F63
A7: Days Payable Outstanding (DPO) | B7: =(365*((HCL_Data!B21+HCL_Data!C21)/2))/(HCL_Data!B69+HCL_Data!B70+HCL_Data!B75) | C7: =(365*((HCL_Data!C21+HCL_Data!D21)/2))/(HCL_Data!C69+HCL_Data!C70+HCL_Data!C75) | D7: =(365*((HCL_Data!D21+HCL_Data!E21)/2))/(HCL_Data!D69+HCL_Data!D70+HCL_Data!D75) | E7: =(365*((HCL_Data!E21+HCL_Data!F21)/2))/(HCL_Data!E69+HCL_Data!E70+HCL_Data!E75) | F7: =(365*((HCL_Data!F21+HCL_Data!G21)/2))/(HCL_Data!F69+HCL_Data!F70+HCL_Data!F75) | H7: =(365*((Wipro_Data!B21+Wipro_Data!C21)/2))/(Wipro_Data!B69+Wipro_Data!B70+Wipro_Data!B75) | I7: =(365*((Wipro_Data!C21+Wipro_Data!D21)/2))/(Wipro_Data!C69+Wipro_Data!C70+Wipro_Data!C75) | J7: =(365*((Wipro_Data!D21+Wipro_Data!E21)/2))/(Wipro_Data!D69+Wipro_Data!D70+Wipro_Data!D75) | K7: =(365*((Wipro_Data!E21+Wipro_Data!F21)/2))/(Wipro_Data!E69+Wipro_Data!E70+Wipro_Data!E75) | L7: =(365*((Wipro_Data!F21+Wipro_Data!G21)/2))/(Wipro_Data!F69+Wipro_Data!F70+Wipro_Data!F75)
A9: Cash Conversion Cycle (CCC) | B9: =B5+B6-B7 | C9: =C5+C6-C7 | D9: =D5+D6-D7 | E9: =E5+E6-E7 | F9: =F5+F6-F7 | H9: =H5+H6-H7 | I9: =I5+I6-I7 | J9: =J5+J6-J7 | K9: =K5+K6-K7 | L9: =L5+L6-L7
